Workbook

Sheet Summary
A1: Player Statistics Criteria
A2: The Red Colums Represent the Weighted points for each of the 5 major stats
A3: Multipliers for the season in which each player played are applied to the weighted statistic to generate a player profile that acconts for both the nuances accross basketball ERAs as well as the number of games each player played in a season relative to their total career games played to provide standardized statistics for a full&fair career evaluation
A5: Columns with Calculated Statistics for Total Player Stat Points: F,H,J,L,N
A6: Columns with Era Multipliers: Cols AE-AI
A7: Column for Player Games Played as % of Career: Col D
A9: Player Accolades & Winning Criteria
A10: Points for a player's accolades, championships & individual accomplishments are distributed based on the rarity of the award, the appreciation for that award among players/coaches/media
A11: For each accolade, the points are designed to enhance the player's historical stats but not remove a player from the top of the list if they have a very impressive stat profile. Vice-versa, the points are not high enough so that they catapult a player with a lot of accomplishments to the top of the list simply bc they have won the most championships or made the most All-NBA teams.
A13: After an evaluation of the top point earners in each of the two sets of player criteria, this model establishes a pretty fair 70/30 relationship between points earned for career stats and points for accolades & winning respectively
A15: Optional Player Stats to Consider Adding
A16: PER (Player Efficiency Rating) since we don't have to weigh/normalize accross eras/years. But since advanced shooting/stats have only been around since 1996, it will skew towards new players
... A20: 2pts for Slam Dunk or 3pt Contest Champion and 3pts for an Olympic Gold Medal

Sheet Player Winning & Accolades Mast
A1: Player | B1: 1st_NBA | C1: 2nd_NBA | D1: 3rd_NBA | E1: 1st_Def | F1: 2nd_Def | G1: Total_All_NBA_Accolades | H1: NBA Championship | I1: NBA_Finals_MVP | J1: Regular_Season_MVP | K1: DPOY | L1: ROY | M1: 6MOY | N1: All-Star_Games | O1: Scoring_Title | P1: Assists_Leader | Q1: Rebounding_Leader | R1: Steals_Leader | S1: Blocks_Leader | T1: Seasons_Plaued | U1: Playoff_Seasons | V1: Legacy_Impact
A2: LeBron James | B2: 13 | C2: 3 | D2: 4 | E2: 5 | F2: 1 | G2: 26 | H2: 4 | I2: 4 | J2: 4 | L2: 1 | N2: 21 | O2: 1 | P2: 1 | T2: 22 | U2: 18 | V2: 50
A3: Kareem Abdul-Jabbar | B3: 10 | C3: 5 | D3: 0 | E3: 5 | F3: 6 | G3: 26 | H3: 6 | I3: 2 | J3: 6 | L3: 1 | N3: 19 | O3: 2 | Q3: 1 | S3: 4 | T3: 20 | U3: 18 | V3: 46
A4: Karl Malone | B4: 11 | C4: 2 | D4: 1 | E4: 3 | F4: 1 | G4: 18 | J4: 2 | N4: 14 | T4: 19 | U4: 19 | V4: 27
A5: Wilt Chamberlain | B5: 7 | C5: 3 | D5: 0 | E5: 2 | F5: 0 | G5: 12 | H5: 2 | I5: 1 | J5: 4 | L5: 1 | N5: 13 | O5: 7 | Q5: 11 | T5: 14 | U5: 13 | V5: 42
A6: Kobe Bryant | B6: 11 | C6: 2 | D6: 2 | E6: 9 | F6: 3 | G6: 27 | H6: 5 | I6: 2 | J6: 1 | N6: 18 | O6: 2 | T6: 20 | U6: 15 | V6: 50
A7: Michael Jordan | B7: 10 | C7: 1 | D7: 0 | E7: 9 | F7: 0 | G7: 20 | H7: 6 | I7: 6 | J7: 5 | K7: 1 | L7: 1 | N7: 14 | O7: 10 | R7: 3 | T7: 15 | U7: 13 | V7: 50
A8: Dirk Nowitzki | B8: 4 | C8: 5 | D8: 3 | E8: 0 | F8: 0 | G8: 12 | H8: 1 | I8: 1 | J8: 1 | N8: 14 | T8: 21 | U8: 15 | V8: 23
A9: Kevin Durant | B9: 6 | C9: 5 | D9: 0 | E9: 0 | F9: 0 | G9: 11 | H9: 2 | I9: 2 | J9: 1 | L9: 1 | N9: 11 | O9: 4 | T9: 17 | U9: 13 | V9: 37
A10: Julius Erving | B10: 5 | C10: 2 | D10: 0 | E10: 1 | F10: 0 | G10: 8 | H10: 1 | J10: 4 | N10: 16 | O10: 3 | T10: 16 | U10: 16 | V10: 46
A11: Shaquille O'Neal | B11: 8 | C11: 2 | D11: 4 | E11: 0 | F11: 3 | G11: 17 | H11: 4 | I11: 3 | J11: 1 | L11: 1 | N11: 15 | O11: 2 | T11: 19 | U11: 17 | V11: 45
A12: Dominique Wilkins | B12: 1 | C12: 4 | D12: 2 | E12: 0 | F12: 0 | G12: 7 | N12: 7 | O12: 1 | T12: 15 | U12: 10 | V12: 34
A13: Allen Iverson | B13: 3 | C13: 3 | D13: 1 | E13: 0 | F13: 0 | G13: 7 | J13: 1 | L13: 1 | N13: 11 | O13: 4 | R13: 3 | T13: 14 | U13: 8 | V13: 44
A14: Hakeem Olajuwon | B14: 6 | C14: 3 | D14: 3 | E14: 5 | F14: 4 | G14: 21 | H14: 2 | I14: 2 | J14: 1 | K14: 2 | N14: 12 | Q14: 2 | S14: 3 | T14: 18 | U14: 15 | V14: 30
A15: Oscar Robertson | B15: 9 | C15: 2 | D15: 0 | E15: 0 | F15: 0 | G15: 11 | H15: 1 | J15: 1 | L15: 1 | N15: 12 | O15: 1 | P15: 6 | T15: 14 | U15: 10 | V15: 28
A16: Tim Duncan | B16: 10 | C16: 3 | D16: 2 | E16: 8 | F16: 7 | G16: 30 | H16: 5 | I16: 3 | J16: 2 | L16: 1 | N16: 15 | T16: 19 | U16: 18 | V16: 32
A17: John Havlicek | B17: 4 | C17: 7 | D17: 0 | E17: 5 | F17: 3 | G17: 19 | H17: 8 | I17: 1 | N17: 13 | T17: 16 | U17: 13 | V17: 24
A18: Kevin Garnett | B18: 4 | C18: 3 | D18: 2 | E18: 9 | F18: 3 | G18: 21 | H18: 1 | J18: 1 | K18: 1 | N18: 15 | Q18: 4 | T18: 21 | U18: 14 | V18: 38
A19: Jerry West | B19: 10 | C19: 2 | D19: 0 | E19: 4 | F19: 1 | G19: 17 | H19: 1 | I19: 1 | N19: 14 | O19: 1 | P19: 1 | T19: 14 | U19: 13 | V19: 48
A20: Stephen Curry | B20: 4 | C20: 4 | D20: 2 | E20: 0 | F20: 0 | G20: 10 | H20: 4 | I20: 1 | J20: 2 | N20: 11 | O20: 2 | R20: 1 | T20: 16 | U20: 10 | V20: 50
A21: Dwyane Wade | B21: 2 | C21: 3 | D21: 3 | E21: 0 | F21: 3 | G21: 11 | H21: 3 | I21: 1 | N21: 13 | O21: 1 | T21: 16 | U21: 13 | V21: 37
A22: Gary Payton | B22: 2 | C22: 5 | D22: 2 | E22: 9 | F22: 0 | G22: 18 | H22: 1 | K22: 1 | N22: 9 | R22: 1 | T22: 17 | U22: 15 | V22: 32
A23: Chris Paul | B23: 4 | C23: 5 | D23: 2 | E23: 7 | F23: 2 | G23: 20 | L23: 1 | N23: 12 | P23: 5 | R23: 6 | T23: 20 | U23: 15 | V23: 25
A24: Larry Bird | B24: 9 | C24: 1 | D24: 0 | E24: 0 | F24: 3 | G24: 13 | H24: 3 | I24: 2 | J24: 3 | L24: 1 | N24: 12 | T24: 13 | U24: 9 | V24: 50
A25: David Robinson | B25: 4 | C25: 2 | D25: 4 | E25: 4 | F25: 4 | G25: 18 | H25: 2 | J25: 1 | K25: 1 | L25: 1 | N25: 10 | O25: 1 | Q25: 1 | S25: 1 | T25: 14 | U25: 12 | V25: 30
A26: John Stockton | B26: 2 | C26: 6 | D26: 3 | E26: 0 | F26: 5 | G26: 16 | N26: 10 | P26: 9 | R26: 2 | T26: 19 | U26: 19 | V26: 28
A27: Jason Kidd | B27: 5 | C27: 1 | D27: 0 | E27: 4 | F27: 5 | G27: 15 | H27: 1 | L27: 1 | N27: 10 | P27: 5 | T27: 19 | U27: 17 | V27: 32
A28: Magic Johnson | B28: 9 | C28: 1 | D28: 0 | E28: 0 | F28: 0 | G28: 10 | H28: 5 | I28: 3 | J28: 3 | N28: 12 | P28: 4 | R28: 2 | T28: 13 | U28: 13 | V28: 50
A29: Bob Cousy | B29: 10 | C29: 2 | D29: 0 | E29: 0 | F29: 0 | G29: 12 | H29: 6 | J29: 1 | P29: 8 | T29: 14 | U29: 13 | V29: 20
A30: Bill Russell | B30: 3 | C30: 8 | D30: 0 | E30: 1 | F30: 0 | G30: 12 | H30: 11 | J30: 5 | N30: 12 | Q30: 5 | T30: 13 | U30: 13 | V30: 47
A31: Isiah Thomas | B31: 3 | C31: 2 | D31: 0 | E31: 0 | F31: 0 | G31: 5 | H31: 2 | I31: 1 | N31: 12 | P31: 1 | T31: 13 | U31: 9 | V31: 35
A32: Giannis Antetokounmpo | B32: 7 | C32: 2 | E32: 4 | F32: 1 | G32: 14 | H32: 1 | I32: 1 | J32: 2 | K32: 1 | N32: 9 | T32: 12 | U32: 9 | V32: 35
A33: Moses Malone | B33: 4 | C33: 4 | E33: 1 | F33: 1 | H33: 1 | I33: 1 | J33: 3 | N33: 13 | Q33: 6 | T33: 21 | U33: 13 | V33: 30
A34: Nikola Jokic | B34: 5 | C34: 2 | H34: 1 | I34: 1 | J34: 3 | N34: 7 | T34: 10 | U34: 7 | V34: 30

Sheet Player Stats Master File
A1: Player | B1: Position | C1: Season | D1: Season Stat Share of Career | E1: PPG | F1: Weighted PPG | G1: Assists Per Game | H1: Weighted Assists Per Game | I1: Total Rebounds Per Game | J1: Weighted Rebounds Per Game | K1: Steals Per Game | L1: Weighted Steals Per Game | M1: Blocks Per Game | N1: Weighted Blocks Per Game | O1: True Shooting PCT | P1: Career Points | Q1: Career Rebounds | R1: Career Assists | S1: Career Blocks | T1: Career Steals | U1: Career PPG | V1: Career RPG | W1: Career Assists PG | X1: Career Blocks PG | Y1: Career Steals PG | Z1: League Avg Points | AA1: League Avg Assists | AB1: League Avg Blocks | AC1: League Avg Rebounds | AD1: League Avg Steal | AE1: Era Multiplier Points | AF1: Era Multiplier Rebounds | AG1: Era Multiplier Steals | AH1: Era Multiplier Blocks | AI1: Era Multiplier Assists
A2: Allen Iverson | B2: G | C2: 1997 | D2: 0.07143 | E2: 23.5 | F2: =(E2*D2)*AE2 -> 2.0579697 | G2: 7.5 | H2: =(G2*D2)*AI2 -> 0.65504542 | I2: 4.1 | J2: =(I2*D2)*AF2 -> 0.52373305 | K2: 3.0986842 | L2: =iferror((K2*D2)*AG2,"No Stat") -> 0.25912867 | M2: 0.47368421 | N2: =iferror((M2*D2)*AH2,"No Stat") -> 0.038668867 | O2: 0.513 | P2: 27457 | Q2: 3839 | R2: 6488 | S2: 185 | T2: 2213 | U2: 25.8055 | V2: 3.6081 | W2: 6.0977 | X2: 0.1739 | Y2: 2.0799 | Z2: 96.9 | AA2: 22 | AB2: 4.9 | AC2: 41.1 | AD2: 8.2 | AE2: 1.226 | AF2: 1.788321 | AG2: 1.170732 | AH2: 1.142857 | AI2: 1.222727
A3: Allen Iverson | B3: G | C3: 1998 | D3: 0.07519 | E3: 22 | F3: =(E3*D3)*AE3 -> 2.0556495 | G3: 6.2 | H3: =(G3*D3)*AI3 -> 0.57000843 | I3: 3.7 | J3: =(I3*D3)*AF3 -> 0.49272088 | K3: 3.3 | L3: =iferror((K3*D3)*AG3,"No Stat") -> 0.28357368 | M3: 0.46875 | N3: =iferror((M3*D3)*AH3,"No Stat") -> 0.038700728 | O3: 0.535 | P3: 27457 | Q3: 3839 | R3: 6488 | S3: 185 | T3: 2213 | U3: 25.8055 | V3: 3.6081 | W3: 6.0977 | X3: 0.1739 | Y3: 2.0799 | Z3: 95.6 | AA3: 22 | AB3: 5.1 | AC3: 41.5 | AD3: 8.4 | AE3: 1.2427 | AF3: 1.771084 | AG3: 1.142857 | AH3: 1.098039 | AI3: 1.222727
A4: Allen Iverson | B4: G | C4: 1999 | D4: 0.04511 | E4: 26.8 | F4: =(E4*D4)*AE4 -> 1.5678847 | G4: 4.6 | H4: =(G4*D4)*AI4 -> 0.26965757 | I4: 4.9 | J4: =(I4*D4)*AF4 -> 0.38960113 | K4: 3.4375 | L4: =iferror((K4*D4)*AG4,"No Stat") -> 0.17721783 | M4: 0.21875 | N4: =iferror((M4*D4)*AH4,"No Stat") -> 0.01105195 | O4: 0.508 | P4: 27457 | Q4: 3839 | R4: 6488 | S4: 185 | T4: 2213 | U4: 25.8055 | V4: 3.6081 | W4: 6.0977 | X4: 0.1739 | Y4: 2.0799 | Z4: 91.6 | AA4: 20.7 | AB4: 5 | AC4: 41.7 | AD4: 8.4 | AE4: 1.2969 | AF4: 1.76259 | AG4: 1.142857 | AH4: 1.12 | AI4: 1.299517
A5: Allen Iverson | B5: G | C5: 2000 | D5: 0.06579 | E5: 28.4 | F5: =(E5*D5)*AE5 -> 2.2766893 | G5: 4.7 | H5: =(G5*D5)*AI5 -> 0.37299684 | I5: 3.8 | J5: =(I5*D5)*AF5 -> 0.42832518 | K5: 3.0857143 | L5: =iferror((K5*D5)*AG5,"No Stat") -> 0.24669468 | M5: 0.10714286 | N5: =iferror((M5*D5)*AH5,"No Stat") -> 0.0075911533 | O5: 0.496 | P5: 27457 | Q5: 3839 | R5: 6488 | S5: 185 | T5: 2213 | U5: 25.8055 | V5: 3.6081 | W5: 6.0977 | X5: 0.1739 | Y5: 2.0799 | Z5: 97.5 | AA5: 22.3 | AB5: 5.2 | AC5: 42.9 | AD5: 7.9 | AE5: 1.2185 | AF5: 1.713287 | AG5: 1.21519 | AH5: 1.076923 | AI5: 1.206278
A6: Allen Iverson | B6: G | C6: 2001 | D6: 0.06673 | E6: 31.1 | F6: =(E6*D6)*AE6 -> 2.6007697 | G6: 4.6 | H6: =(G6*D6)*AI6 -> 0.37876929 | I6: 3.8 | J6: =(I6*D6)*AF6 -> 0.43853392 | K6: 3.7605634 | L6: =iferror((K6*D6)*AG6,"No Stat") -> 0.30885212 | M6: 0.42253521 | N6: =iferror((M6*D6)*AH6,"No Stat") -> 0.029791768 | O6: 0.518 | P6: 27457 | Q6: 3839 | R6: 6488 | S6: 185 | T6: 2213 | U6: 25.8055 | V6: 3.6081 | W6: 6.0977 | X6: 0.1739 | Y6: 2.0799 | Z6: 94.8 | AA6: 21.8 | AB6: 5.3 | AC6: 42.5 | AD6: 7.8 | AE6: 1.2532 | AF6: 1.729412 | AG6: 1.230769 | AH6: 1.056604 | AI6: 1.233945
A7: Allen Iverson | B7: G | C7: 2002 | D7: 0.05639 | E7: 31.4 | F7: =(E7*D7)*AE7 -> 2.2026836 | G7: 5.5 | H7: =(G7*D7)*AI7 -> 0.38095452 | I7: 4.5 | J7: =(I7*D7)*AF7 -> 0.43988201 | K7: 4.2 | L7: =iferror((K7*D7)*AG7,"No Stat") -> 0.29149287 | M7: 0.325 | N7: =iferror((M7*D7)*AH7,"No Stat") -> 0.019736499 | O7: 0.489 | P7: 27457 | Q7: 3839 | R7: 6488 | S7: 185 | T7: 2213 | U7: 25.8055 | V7: 3.6081 | W7: 6.0977 | X7: 0.1739 | Y7: 2.0799 | Z7: 95.5 | AA7: 21.9 | AB7: 5.2 | AC7: 42.4 | AD7: 7.8 | AE7: 1.244 | AF7: 1.733491 | AG7: 1.230769 | AH7: 1.076923 | AI7: 1.228311
A8: Allen Iverson | B8: G | C8: 2003 | D8: 0.07707 | E8: 27.6 | F8: =(E8*D8)*AE8 -> 2.6572133 | G8: 5.5 | H8: =(G8*D8)*AI8 -> 0.53034923 | I8: 4.2 | J8: =(I8*D8)*AF8 -> 0.56244713 | K8: 4.1158537 | L8: =iferror((K8*D8)*AG8,"No Stat") -> 0.38546901 | M8: 0.23780488 | N8: =iferror((M8*D8)*AH8,"No Stat") -> 0.020526937 | O8: 0.5 | P8: 27457 | Q8: 3839 | R8: 6488 | S8: 185 | T8: 2213 | U8: 25.8055 | V8: 3.6081 | W8: 6.0977 | X8: 0.1739 | Y8: 2.0799 | Z8: 95.1 | AA8: 21.5 | AB8: 5 | AC8: 42.3 | AD8: 7.9 | AE8: 1.2492 | AF8: 1.737589 | AG8: 1.21519 | AH8: 1.12 | AI8: 1.251163
A9: Allen Iverson | B9: G | C9: 2004 | D9: 0.04511 | E9: 26.4 | F9: =(E9*D9)*AE9 -> 1.5147108 | G9: 6.8 | H9: =(G9*D9)*AI9 -> 0.38739542 | I9: 3.7 | J9: =(I9*D9)*AF9 -> 0.29070292 | K9: 3.59375 | L9: =iferror((K9*D9)*AG9,"No Stat") -> 0.19699939 | M9: 0.15625 | N9: =iferror((M9*D9)*AH9,"No Stat") -> 0.0077394593 | O9: 0.478 | P9: 27457 | Q9: 3839 | R9: 6488 | S9: 185 | T9: 2213 | U9: 25.8055 | V9: 3.6081 | W9: 6.0977 | X9: 0.1739 | Y9: 2.0799 | Z9: 93.4 | AA9: 21.3 | AB9: 5.1 | AC9: 42.2 | AD9: 7.9 | AE9: 1.2719 | AF9: 1.741706 | AG9: 1.21519 | AH9: 1.098039 | AI9: 1.262911
A10: Allen Iverson | B10: G | C10: 2005 | D10: 0.07049 | E10: 30.7 | F10: =(E10*D10)*AE10 -> 2.6448934 | G10: 7.9 | H10: =(G10*D10)*AI10 -> 0.70327851 | I10: 4 | J10: =(I10*D10)*AF10 -> 0.49460775 | K10: 3.6 | L10: =iferror((K10*D10)*AG10,"No Stat") -> 0.32481792 | M10: 0.18 | N10: =iferror((M10*D10)*AH10,"No Stat") -> 0.014500798 | O10: 0.532 | P10: 27457 | Q10: 3839 | R10: 6488 | S10: 185 | T10: 2213 | U10: 25.8055 | V10: 3.6081 | W10: 6.0977 | X10: 0.1739 | Y10: 2.0799 | Z10: 97.2 | AA10: 21.3 | AB10: 4.9 | AC10: 41.9 | AD10: 7.5 | AE10: 1.2222 | AF10: 1.754177 | AG10: 1.28 | AH10: 1.142857 | AI10: 1.262911 | AM10: Career Winning % Regular Season | AN10: Career Winning % Post-Season
A11: Allen Iverson | B11: G | C11: 2006 | D11: 0.06767 | E11: 33 | F11: =(E11*D11)*AE11 -> 2.7348898 | G11: 7.4 | H11: =(G11*D11)*AI11 -> 0.65390232 | I11: 3.2 | J11: =(I11*D11)*AF11 -> 0.38819475 | K11: 2.9166667 | L11: =iferror((K11*D11)*AG11,"No Stat") -> 0.26316105 | M11: 0.20833333 | N11: =iferror((M11*D11)*AH11,"No Stat") -> 0.016797513 | O11: 0.543 | P11: 27457 | Q11: 3839 | R11: 6488 | S11: 185 | T11: 2213 | U11: 25.8055 | V11: 3.6081 | W11: 6.0977 | X11: 0.1739 | Y11: 2.0799 | Z11: 97 | AA11: 20.6 | AB11: 4.7 | AC11: 41 | AD11: 7.2 | AE11: 1.2247 | AF11: 1.792683 | AG11: 1.333333 | AH11: 1.191489 | AI11: 1.305825 | AM11: 0.51 | AN11: 0.422
A12: Allen Iverson | B12: G | C12: 2007 | D12: 0.12218 | E12: 27.433 | F12: =(E12*D12)*AE12 -> 4.0341831 | G12: 7.233 | H12: =(G12*D12)*AI12 -> 1.1160697 | I12: 2.9 | J12: =(I12*D12)*AF12 -> 0.63364147 | K12: 1.8923077 | L12: =iferror((K12*D12)*AG12,"No Stat") -> 0.30826946 | M12: 0.2 | N12: =iferror((M12*D12)*AH12,"No Stat") -> 0.029748166 | O12: 0.538 | P12: 27457 | Q12: 3839 | R12: 6488 | S12: 185 | T12: 2213 | U12: 25.8055 | V12: 3.6081 | W12: 6.0977 | X12: 0.1739 | Y12: 2.0799 | Z12: 98.7 | AA12: 21.3 | AB12: 4.6 | AC12: 41.1 | AD12: 7.2 | AE12: 1.2036 | AF12: 1.788321 | AG12: 1.333333 | AH12: 1.217391 | AI12: 1.262911 | AM12: 0.717 | AN12: 0.648
A13: Allen Iverson | B13: G | C13: 2008 | D13: 0.07707 | E13: 26.4 | F13: =(E13*D13)*AE13 -> 2.4196034 | G13: 7.1 | H13: =(G13*D13)*AI13 -> 0.675211 | I13: 3 | J13: =(I13*D13)*AF13 -> 0.4046175 | K13: 2.9268293 | L13: =iferror((K13*D13)*AG13,"No Stat") -> 0.29664085 | M13: 0.21951219 | N13: =iferror((M13*D13)*AH13,"No Stat") -> 0.020157378 | O13: 0.567 | P13: 27457 | Q13: 3839 | R13: 6488 | S13: 185 | T13: 2213 | U13: 25.8055 | V13: 3.6081 | W13: 6.0977 | X13: 0.1739 | Y13: 2.0799 | Z13: 99.9 | AA13: 21.8 | AB13: 4.7 | AC13: 42 | AD13: 7.3 | AE13: 1.1892 | AF13: 1.75 | AG13: 1.315068 | AH13: 1.191489 | AI13: 1.233945 | AM13: 0.655 | AN13: 0.578
A14: Allen Iverson | B14: G | C14: 2009 | D14: 0.10714 | E14: 17.867 | F14: =(E14*D14)*AE14 -> 2.2741532 | G14: 5.533 | H14: =(G14*D14)*AI14 -> 0.75935554 | I14: 2.933 | J14: =(I14*D14)*AF14 -> 0.55924356 | K14: 1.5438596 | L14: =iferror((K14*D14)*AG14,"No Stat") -> 0.21752424 | M14: 0.10526316 | N14: =iferror((M14*D14)*AH14,"No Stat") -> 0.013157548 | O14: 0.518 | P14: 27457 | Q14: 3839 | R14: 6488 | S14: 185 | T14: 2213 | U14: 25.8055 | V14: 3.6081 | W14: 6.0977 | X14: 0.1739 | Y14: 2.0799 | Z14: 100 | AA14: 21 | AB14: 4.8 | AC14: 41.3 | AD14: 7.3 | AE14: 1.188 | AF14: 1.779661 | AG14: 1.315068 | AH14: 1.166667 | AI14: 1.280952 | AM14: 0.629 | AN14: 0.51
A15: Allen Iverson | B15: G | C15: 2010 | D15: 0.05263 | E15: 13.333 | F15: =(E15*D15)*AE15 -> 0.83034029 | G15: 3.933 | H15: =(G15*D15)*AI15 -> 0.2626478 | I15: 2.367 | J15: =(I15*D15)*AF15 -> 0.21957502 | K15: 0.67857143 | L15: =iferror((K15*D15)*AG15,"No Stat") -> 0.047617607 | M15: 0.071428571 | N15: =iferror((M15*D15)*AH15,"No Stat") -> 0.004296326 | O15: 0.538 | P15: 27457 | Q15: 3839 | R15: 6488 | S15: 185 | T15: 2213 | U15: 25.8055 | V15: 3.6081 | W15: 6.0977 | X15: 0.1739 | Y15: 2.0799 | Z15: 100.4 | AA15: 21.2 | AB15: 4.9 | AC15: 41.7 | AD15: 7.2 | AE15: 1.1833 | AF15: 1.76259 | AG15: 1.333333 | AH15: 1.142857 | AI15: 1.268868 | AM15: 0.682 | AN15: 0.569
A16: Bill Russell | B16: C | C16: 1957 | D16: 0.04984 | E16: 14.7 | F16: =(E16*D16)*AE16 -> 0.87390253 | G16: 1.8 | H16: =(G16*D16)*AI16 -> 0.1276853 | I16: 19.6 | J16: =(I16*D16)*AF16 -> 1.1506335 | K16: 0 | L16: =iferror((K16*D16)*AG16,"No Stat") -> No Stat | M16: 0 | N16: =iferror((M16*D16)*AH16,"No Stat") -> No Stat | O16: 0.45 | P16: 14522 | Q16: 21620 | R16: 4100 | S16: 0 | T16: 0 | U16: 15.08 | V16: 22.4507 | W16: 4.2575 | X16: 0 | Y16: 0 | Z16: 99.6 | AA16: 18.9 | AC16: 62.4 | AE16: 1.1928 | AF16: 1.177885 | AG16: Infinity | AH16: Infinity | AI16: 1.42328 | AM16: 0.602 | AN16: 0.476
A17: Bill Russell | B17: C | C17: 1958 | D17: 0.07165 | E17: 16.6 | F17: =(E17*D17)*AE17 -> 1.3254562 | G17: 2.9 | H17: =(G17*D17)*AI17 -> 0.28517432 | I17: 22.7 | J17: =(I17*D17)*AF17 -> 1.6672872 | K17: 0 | L17: =iferror((K17*D17)*AG17,"No Stat") -> No Stat | M17: 0 | N17: =iferror((M17*D17)*AH17,"No Stat") -> No Stat | O17: 0.465 | P17: 14522 | Q17: 21620 | R17: 4100 | S17: 0 | T17: 0 | U17: 15.08 | V17: 22.4507 | W17: 4.2575 | X17: 0 | Y17: 0 | Z17: 106.6 | AA17: 19.6 | AC17: 71.7 | AE17: 1.1144 | AF17: 1.025105 | AG17: Infinity | AH17: Infinity | AI17: 1.372449 | AM17: 0.529 | AN17: 0.393
A18: Bill Russell | B18: C | C18: 1959 | D18: 0.07269 | E18: 16.7 | F18: =(E18*D18)*AE18 -> 1.3328875 | G18: 3.2 | H18: =(G18*D18)*AI18 -> 0.31924262 | I18: 23 | J18: =(I18*D18)*AF18 -> 1.7554635 | K18: 0 | L18: =iferror((K18*D18)*AG18,"No Stat") -> No Stat | M18: 0 | N18: =iferror((M18*D18)*AH18,"No Stat") -> No Stat | O18: 0.493 | P18: 14522 | Q18: 21620 | R18: 4100 | S18: 0 | T18: 0 | U18: 15.08 | V18: 22.4507 | W18: 4.2575 | X18: 0 | Y18: 0 | Z18: 108.2 | AA18: 19.6 | AC18: 70 | AE18: 1.098 | AF18: 1.05 | AG18: Infinity | AH18: Infinity | AI18: 1.372449 | AM18: 0.58 | AN18: 0.593
A19: Bill Russell | B19: C | C19: 1960 | D19: 0.07684 | E19: 18.2 | F19: =(E19*D19)*AE19 -> 1.441002 | G19: 3.7 | H19: =(G19*D19)*AI19 -> 0.33840186 | I19: 24 | J19: =(I19*D19)*AF19 -> 1.84416 | K19: 0 | L19: =iferror((K19*D19)*AG19,"No Stat") -> No Stat | M19: 0 | N19: =iferror((M19*D19)*AH19,"No Stat") -> No Stat | O19: 0.496 | P19: 14522 | Q19: 21620 | R19: 4100 | S19: 0 | T19: 0 | U19: 15.08 | V19: 22.4507 | W19: 4.2575 | X19: 0 | Y19: 0 | Z19: 115.3 | AA19: 22.6 | AC19: 73.5 | AE19: 1.0304 | AF19: 1 | AG19: Infinity | AH19: Infinity | AI19: 1.190265 | AM19: 0.616 | AN19: 0.519
A20: Bill Russell | B20: C | C20: 1961 | D20: 0.081 | E20: 16.9 | F20: =(E20*D20)*AE20 -> 1.3769765 | G20: 3.4 | H20: =(G20*D20)*AI20 -> 0.30612638 | I20: 23.9 | J20: =(I20*D20)*AF20 -> 1.9411831 | K20: 0 | L20: =iferror((K20*D20)*AG20,"No Stat") -> No Stat | M20: 0 | N20: =iferror((M20*D20)*AH20,"No Stat") -> No Stat | O20: 0.454 | P20: 14522 | Q20: 21620 | R20: 4100 | S20: 0 | T20: 0 | U20: 15.08 | V20: 22.4507 | W20: 4.2575 | X20: 0 | Y20: 0 | Z20: 118.1 | AA20: 24.2 | AC20: 73.3 | AE20: 1.0059 | AF20: 1.002729 | AG20: Infinity | AH20: Infinity | AI20: 1.11157 | AM20: 0.591 | AN20: 0.524
A21: Bill Russell | B21: C | C21: 1962 | D21: 0.07892 | E21: 18.9 | F21: =(E21*D21)*AE21 -> 1.491588 | G21: 4.5 | H21: =(G21*D21)*AI21 -> 0.39971824 | I21: 23.6 | J21: =(I21*D21)*AF21 -> 1.9172922 | K21: 0 | L21: =iferror((K21*D21)*AG21,"No Stat") -> No Stat | M21: 0 | N21: =iferror((M21*D21)*AH21,"No Stat") -> No Stat | O21: 0.489 | P21: 14522 | Q21: 21620 | R21: 4100 | S21: 0 | T21: 0 | U21: 15.08 | V21: 22.4507 | W21: 4.2575 | X21: 0 | Y21: 0 | Z21: 118.8 | AA21: 23.9 | AC21: 71.4 | AE21: 1 | AF21: 1.029412 | AG21: Infinity | AH21: Infinity | AI21: 1.125523 | AM21: 0.579 | AN21: 0.631
A22: Bill Russell | B22: C | C22: 1963 | D22: 0.081 | E22: 16.8 | F22: =(E22*D22)*AE22 -> 1.4021683 | G22: 4.5 | H22: =(G22*D22)*AI22 -> 0.43194052 | I22: 23.6 | J22: =(I22*D22)*AF22 -> 2.1064857 | K22: 0 | L22: =iferror((K22*D22)*AG22,"No Stat") -> No Stat | M22: 0 | N22: =iferror((M22*D22)*AH22,"No Stat") -> No Stat | O22: 0.464 | P22: 14522 | Q22: 21620 | R22: 4100 | S22: 0 | T22: 0 | U22: 15.08 | V22: 22.4507 | W22: 4.2575 | X22: 0 | Y22: 0 | Z22: 115.3 | AA22: 22.7 | AC22: 66.7 | AE22: 1.0304 | AF22: 1.101949 | AG22: Infinity | AH22: Infinity | AI22: 1.185022 | AM22: 0.584 | AN22: 0.5
A23: Bill Russell | B23: C | C23: 1964 | D23: 0.081 | E23: 15 | F23: =(E23*D23)*AE23 -> 1.3004145 | G23: 4.7 | H23: =(G23*D23)*AI23 -> 0.47854333 | I23: 24.7 | J23: =(I23*D23)*AF23 -> 2.2314327 | K23: 0 | L23: =iferror((K23*D23)*AG23,"No Stat") -> No Stat | M23: 0 | N23: =iferror((M23*D23)*AH23,"No Stat") -> No Stat | O23: 0.461 | P23: 14522 | Q23: 21620 | R23: 4100 | S23: 0 | T23: 0 | U23: 15.08 | V23: 22.4507 | W23: 4.2575 | X23: 0 | Y23: 0 | Z23: 111 | AA23: 21.4 | AC23: 65.9 | AE23: 1.0703 | AF23: 1.115326 | AG23: Infinity | AH23: Infinity | AI23: 1.257009 | AM23: 0.638 | AN23: 0.569
A24: Bill Russell | B24: C | C24: 1965 | D24: 0.081 | E24: 14.1 | F24: =(E24*D24)*AE24 -> 1.2267296 | G24: 5.3 | H24: =(G24*D24)*AI24 -> 0.54991269 | I24: 24.1 | J24: =(I24*D24)*AF24 -> 2.1319372 | K24: 0 | L24: =iferror((K24*D24)*AG24,"No Stat") -> No Stat | M24: 0 | N24: =iferror((M24*D24)*AH24,"No Stat") -> No Stat | O24: 0.472 | P24: 14522 | Q24: 21620 | R24: 4100 | S24: 0 | T24: 0 | U24: 15.08 | V24: 22.4507 | W24: 4.2575 | X24: 0 | Y24: 0 | Z24: 110.6 | AA24: 21 | AC24: 67.3 | AE24: 1.0741 | AF24: 1.092125 | AG24: Infinity | AH24: Infinity | AI24: 1.280952 | AM24: 0.649 | AN24: 0.628
A25: Bill Russell | B25: C | C25: 1966 | D25: 0.081 | E25: 12.9 | F25: =(E25*D25)*AE25 -> 1.0747841 | G25: 4.8 | H25: =(G25*D25)*AI25 -> 0.45671247 | I25: 22.8 | J25: =(I25*D25)*AF25 -> 1.9903204 | K25: 0 | L25: =iferror((K25*D25)*AG25,"No Stat") -> No Stat | M25: 0 | N25: =iferror((M25*D25)*AH25,"No Stat") -> No Stat | O25: 0.448 | P25: 14522 | Q25: 21620 | R25: 4100 | S25: 0 | T25: 0 | U25: 15.08 | V25: 22.4507 | W25: 4.2575 | X25: 0 | Y25: 0 | Z25: 115.5 | AA25: 22.9 | AC25: 68.2 | AE25: 1.0286 | AF25: 1.077713 | AG25: Infinity | AH25: Infinity | AI25: 1.174672 | AM25: 0.634 | AN25: 0.489
A26: Bill Russell | B26: C | C26: 1967 | D26: 0.08411 | E26: 13.3 | F26: =(E26*D26)*AE26 -> 1.1319751 | G26: 5.8 | H26: =(G26*D26)*AI26 -> 0.58584124 | I26: 21 | J26: =(I26*D26)*AF26 -> 1.9290313 | K26: 0 | L26: =iferror((K26*D26)*AG26,"No Stat") -> No Stat | M26: 0 | N26: =iferror((M26*D26)*AH26,"No Stat") -> No Stat | O26: 0.5 | P26: 14522 | Q26: 21620 | R26: 4100 | S26: 0 | T26: 0 | U26: 15.08 | V26: 22.4507 | W26: 4.2575 | X26: 0 | Y26: 0 | Z26: 117.4 | AA26: 22.4 | AC26: 67.3 | AE26: 1.0119 | AF26: 1.092125 | AG26: Infinity | AH26: Infinity | AI26: 1.200893 | AM26: 0.673 | AN26: 0.596
A27: Bill Russell | B27: C | C27: 1968 | D27: 0.081 | E27: 12.5 | F27: =(E27*D27)*AE27 -> 1.0316363 | G27: 4.6 | H27: =(G27*D27)*AI27 -> 0.43960279 | I27: 18.6 | J27: =(I27*D27)*AF27 -> 1.6727358 | K27: 0 | L27: =iferror((K27*D27)*AG27,"No Stat") -> No Stat | M27: 0 | N27: =iferror((M27*D27)*AH27,"No Stat") -> No Stat | O27: 0.461 | P27: 14522 | Q27: 21620 | R27: 4100 | S27: 0 | T27: 0 | U27: 15.08 | V27: 22.4507 | W27: 4.2575 | X27: 0 | Y27: 0 | Z27: 116.6 | AA27: 22.8 | AC27: 66.2 | AE27: 1.0189 | AF27: 1.110272 | AG27: Infinity | AH27: Infinity | AI27: 1.179825 | AM27: 0.688 | AN27: 0.65
... A39: Bob Cousy | B39: G | C39: 1961 | D39: 0.08225 | E39: 18.1 | F39: =(E39*D39)*AE39 -> 1.4975085 | G39: 7.7 | H39: =(G39*D39)*AI39 -> 0.70398507 | I39: 4.4 | J39: =(I39*D39)*AF39 -> 0.36288763 | K39: 0 | L39: =iferror((K39*D39)*AG39,"No Stat") -> No Stat | M39: 0 | N39: =iferror((M39*D39)*AH39,"No Stat") -> No Stat | O39: 0.436 | P39: 16960 | Q39: 4786 | R39: 6955 | S39: 0 | T39: 0 | U39: 18.355 | V39: 5.1797 | W39: 7.5271 | X39: 0 | Y39: 0 | Z39: 118.1 | AA39: 24.2 | AC39: 73.3 | AE39: 1.0059 | AF39: 1.002729 | AG39: Infinity | AH39: Infinity | AI39: 1.11157 | AM39: 0.643 | AN39: 0.543
A40: Bob Cousy | B40: G | C40: 1962 | D40: 0.08117 | E40: 15.7 | F40: =(E40*D40)*AE40 -> 1.274369 | G40: 7.8 | H40: =(G40*D40)*AI40 -> 0.71259787 | I40: 3.5 | J40: =(I40*D40)*AF40 -> 0.2924508 | K40: 0 | L40: =iferror((K40*D40)*AG40,"No Stat") -> No Stat | M40: 0 | N40: =iferror((M40*D40)*AH40,"No Stat") -> No Stat | O40: 0.443 | P40: 16960 | Q40: 4786 | R40: 6955 | S40: 0 | T40: 0 | U40: 18.355 | V40: 5.1797 | W40: 7.5271 | X40: 0 | Y40: 0 | Z40: 118.8 | AA40: 23.9 | AC40: 71.4 | AE40: 1 | AF40: 1.029412 | AG40: Infinity | AH40: Infinity | AI40: 1.125523
A41: Bob Cousy | B41: G | C41: 1963 | D41: 0.08225 | E41: 13.2 | F41: =(E41*D41)*AE41 -> 1.1187053 | G41: 6.8 | H41: =(G41*D41)*AI41 -> 0.6627828 | I41: 2.5 | J41: =(I41*D41)*AF41 -> 0.22658826 | K41: 0 | L41: =iferror((K41*D41)*AG41,"No Stat") -> No Stat | M41: 0 | N41: =iferror((M41*D41)*AH41,"No Stat") -> No Stat | O41: 0.448 | P41: 16960 | Q41: 4786 | R41: 6955 | S41: 0 | T41: 0 | U41: 18.355 | V41: 5.1797 | W41: 7.5271 | X41: 0 | Y41: 0 | Z41: 115.3 | AA41: 22.7 | AC41: 66.7 | AE41: 1.0304 | AF41: 1.101949 | AG41: Infinity | AH41: Infinity | AI41: 1.185022 | AK41: Giannis Antetokounmpo | AM41: 0.573 | AN41: 0.524
A42: Bob Cousy | B42: G | C42: 1970 | D42: 0.00758 | E42: 0.7 | F42: =(E42*D42)*AE42 -> 0.005401508 | G42: 1.4 | H42: =(G42*D42)*AI42 -> 0.0115572 | I42: 0.7 | J42: =(I42*D42)*AF42 -> 0.0073722307 | K42: 0 | L42: =iferror((K42*D42)*AG42,"No Stat") -> No Stat | M42: 0 | N42: =iferror((M42*D42)*AH42,"No Stat") -> No Stat | O42: 0.579 | P42: 16960 | Q42: 4786 | R42: 6955 | S42: 0 | T42: 0 | U42: 18.355 | V42: 5.1797 | W42: 7.5271 | X42: 0 | Y42: 0 | Z42: 116.7 | AA42: 24.7 | AC42: 52.9 | AE42: 1.018 | AF42: 1.389414 | AG42: Infinity | AH42: Infinity | AI42: 1.089069 | AK42: Nikola JokiÄ‡ | AM42: 0.607 | AN42: 0.542
A43: Chris Paul | B43: G | C43: 2006 | D43: 0.05923 | E43: 16.1 | F43: =(E43*D43)*AE43 -> 1.1678776 | G43: 7.8 | H43: =(G43*D43)*AI43 -> 0.60328332 | I43: 5.1 | J43: =(I43*D43)*AF43 -> 0.54152113 | K43: 3.3653846 | L43: =iferror((K43*D43)*AG43,"No Stat") -> 0.26577557 | M43: 0.11538461 | N43: =iferror((M43*D43)*AH43,"No Stat") -> 0.0081429108 | O43: 0.546 | P43: 22714 | Q43: 5869 | R43: 12263 | S43: 210 | T43: 2672 | U43: 17.2468 | V43: 4.4563 | W43: 9.3113 | X43: 0.1595 | Y43: 2.0289 | Z43: 97 | AA43: 20.6 | AB43: 4.7 | AC43: 41 | AD43: 7.2 | AE43: 1.2247 | AF43: 1.792683 | AG43: 1.333333 | AH43: 1.191489 | AI43: 1.305825 | AK43: Moses Malone | AM43: 0.546 | AN43: 0.516
A44: Chris Paul | B44: G | C44: 2007 | D44: 0.0486 | E44: 17.3 | F44: =(E44*D44)*AE44 -> 1.0119628 | G44: 8.9 | H44: =(G44*D44)*AI44 -> 0.54625952 | I44: 4.4 | J44: =(I44*D44)*AF44 -> 0.38241456 | K44: 2.765625 | L44: =iferror((K44*D44)*AG44,"No Stat") -> 0.17921246 | M44: 0.0703125 | N44: =iferror((M44*D44)*AH44,"No Stat") -> 0.0041600533 | O44: 0.537 | P44: 22714 | Q44: 5869 | R44: 12263 | S44: 210 | T44: 2672 | U44: 17.2468 | V44: 4.4563 | W44: 9.3113 | X44: 0.1595 | Y44: 2.0289 | Z44: 98.7 | AA44: 21.3 | AB44: 4.6 | AC44: 41.1 | AD44: 7.2 | AE44: 1.2036 | AF44: 1.788321 | AG44: 1.333333 | AH44: 1.217391 | AI44: 1.262911
A45: Chris Paul | B45: G | C45: 2008 | D45: 0.06074 | E45: 21.1 | F45: =(E45*D45)*AE45 -> 1.5240954 | G45: 11.6 | H45: =(G45*D45)*AI45 -> 0.8694179 | I45: 4 | J45: =(I45*D45)*AF45 -> 0.42518 | K45: 4.06875 | L45: =iferror((K45*D45)*AG45,"No Stat") -> 0.32500048 | M45: 0.075 | N45: =iferror((M45*D45)*AH45,"No Stat") -> 0.0054278281 | O45: 0.576 | P45: 22714 | Q45: 5869 | R45: 12263 | S45: 210 | T45: 2672 | U45: 17.2468 | V45: 4.4563 | W45: 9.3113 | X45: 0.1595 | Y45: 2.0289 | Z45: 99.9 | AA45: 21.8 | AB45: 4.7 | AC45: 42 | AD45: 7.3 | AE45: 1.1892 | AF45: 1.75 | AG45: 1.315068 | AH45: 1.191489 | AI45: 1.233945
A46: Chris Paul | B46: G | C46: 2009 | D46: 0.05923 | E46: 22.8 | F46: =(E46*D46)*AE46 -> 1.6043275 | G46: 11 | H46: =(G46*D46)*AI46 -> 0.83457866 | I46: 5.5 | J46: =(I46*D46)*AF46 -> 0.57975127 | K46: 4.1538462 | L46: =iferror((K46*D46)*AG46,"No Stat") -> 0.32354921 | M46: 0.19230769 | N46: =iferror((M46*D46)*AH46,"No Stat") -> 0.013288786 | O46: 0.599 | P46: 22714 | Q46: 5869 | R46: 12263 | S46: 210 | T46: 2672 | U46: 17.2468 | V46: 4.4563 | W46: 9.3113 | X46: 0.1595 | Y46: 2.0289 | Z46: 100 | AA46: 21 | AB46: 4.8 | AC46: 41.3 | AD46: 7.3 | AE46: 1.188 | AF46: 1.779661 | AG46: 1.315068 | AH46: 1.166667 | AI46: 1.280952
A47: Chris Paul | B47: G | C47: 2010 | D47: 0.03417 | E47: 18.7 | F47: =(E47*D47)*AE47 -> 0.75610385 | G47: 10.7 | H47: =(G47*D47)*AI47 -> 0.46392225 | I47: 4.2 | J47: =(I47*D47)*AF47 -> 0.25295634 | K47: 3.2 | L47: =iferror((K47*D47)*AG47,"No Stat") -> 0.14579196 | M47: 0.26666667 | N47: =iferror((M47*D47)*AH47,"No Stat") -> 0.010413713 | O47: 0.584 | P47: 22714 | Q47: 5869 | R47: 12263 | S47: 210 | T47: 2672 | U47: 17.2468 | V47: 4.4563 | W47: 9.3113 | X47: 0.1595 | Y47: 2.0289 | Z47: 100.4 | AA47: 21.2 | AB47: 4.9 | AC47: 41.7 | AD47: 7.2 | AE47: 1.1833 | AF47: 1.76259 | AG47: 1.333333 | AH47: 1.142857 | AI47: 1.268868
A48: Chris Paul | B48: G | C48: 2011 | D48: 0.06074 | E48: 15.9 | F48: =(E48*D48)*AE48 -> 1.1519657 | G48: 9.8 | H48: =(G48*D48)*AI48 -> 0.74475728 | I48: 4.1 | J48: =(I48*D48)*AF48 -> 0.4421255 | K48: 3.525 | L48: =iferror((K48*D48)*AG48,"No Stat") -> 0.28156724 | M48: 0.09375 | N48: =iferror((M48*D48)*AH48,"No Stat") -> 0.0065078563 | O48: 0.578 | P48: 22714 | Q48: 5869 | R48: 12263 | S48: 210 | T48: 2672 | U48: 17.2468 | V48: 4.4563 | W48: 9.3113 | X48: 0.1595 | Y48: 2.0289 | Z48: 99.6 | AA48: 21.5 | AB48: 4.9 | AC48: 41.4 | AD48: 7.3 | AE48: 1.1928 | AF48: 1.775362 | AG48: 1.315068 | AH48: 1.142857 | AI48: 1.251163
A49: Chris Paul | B49: G | C49: 2012 | D49: 0.04556 | E49: 19.8 | F49: =(E49*D49)*AE49 -> 1.1128158 | G49: 9.1 | H49: =(G49*D49)*AI49 -> 0.53107758 | I49: 3.6 | J49: =(I49*D49)*AF49 -> 0.28566765 | K49: 3.8 | L49: =iferror((K49*D49)*AG49,"No Stat") -> 0.21584785 | M49: 0.1 | N49: =iferror((M49*D49)*AH49,"No Stat") -> 0.0050026657 | O49: 0.581 | P49: 22714 | Q49: 5869 | R49: 12263 | S49: 210 | T49: 2672 | U49: 17.2468 | V49: 4.4563 | W49: 9.3113 | X49: 0.1595 | Y49: 2.0289 | Z49: 96.3 | AA49: 21 | AB49: 5.1 | AC49: 42.2 | AD49: 7.7 | AE49: 1.2336 | AF49: 1.741706 | AG49: 1.246753 | AH49: 1.098039 | AI49: 1.280952
A50: Chris Paul | B50: G | C50: 2013 | D50: 0.05315 | E50: 16.9 | F50: =(E50*D50)*AE50 -> 1.0877626 | G50: 9.7 | H50: =(G50*D50)*AI50 -> 0.62753097 | I50: 3.7 | J50: =(I50*D50)*AF50 -> 0.34332876 | K50: 3.6214286 | L50: =iferror((K50*D50)*AG50,"No Stat") -> 0.2368971 | M50: 0.21428571 | N50: =iferror((M50*D50)*AH50,"No Stat") -> 0.01250588 | O50: 0.594 | P50: 22714 | Q50: 5869 | R50: 12263 | S50: 210 | T50: 2672 | U50: 17.2468 | V50: 4.4563 | W50: 9.3113 | X50: 0.1595 | Y50: 2.0289 | Z50: 98.1 | AA50: 22.1 | AB50: 5.1 | AC50: 42.1 | AD50: 7.8 | AE50: 1.211 | AF50: 1.745843 | AG50: 1.230769 | AH50: 1.098039 | AI50: 1.217195
A51: Chris Paul | B51: G | C51: 2014 | D51: 0.04708 | E51: 19.1 | F51: =(E51*D51)*AE51 -> 1.057672 | G51: 10.7 | H51: =(G51*D51)*AI51 -> 0.61595606 | I51: 4.3 | J51: =(I51*D51)*AF51 -> 0.34846908 | K51: 3.7258065 | L51: =iferror((K51*D51)*AG51,"No Stat") -> 0.21869415 | M51: 0.096774194 | N51: =iferror((M51*D51)*AH51,"No Stat") -> 0.0054285777 | O51: 0.58 | P51: 22714 | Q51: 5869 | R51: 12263 | S51: 210 | T51: 2672 | U51: 17.2468 | V51: 4.4563 | W51: 9.3113 | X51: 0.1595 | Y51: 2.0289 | Z51: 101 | AA51: 22 | AB51: 4.7 | AC51: 42.7 | AD51: 7.7 | AE51: 1.1762 | AF51: 1.721311 | AG51: 1.246753 | AH51: 1.191489 | AI51: 1.222727
...

Sheet Calculate Player Points from Cr
A1: SELECT Player
A2: Dominique Wilkins | B2: POS | C2: Points | D2: Assists | E2: Rebounds | F2: Steals | G2: Blocks | H2: Total Points for Stats
B3: =vlookup(A2,'Player Stats Master File'!A2:B528,2,FALSE) -> F | C3: =sumif('Player Stats Master File'!A:A,A2,'Player Stats Master File'!F:F) -> 27.868281 | D3: =sumif('Player Stats Master File'!A:A,A2,'Player Stats Master File'!H:H) -> 2.6762678 | E3: =sumif('Player Stats Master File'!A:A,A2,'Player Stats Master File'!J:J) -> 11.343518 | F3: =sumif('Player Stats Master File'!A:A,A2,'Player Stats Master File'!L:L) -> 2.0449294 | G3: =sumif('Player Stats Master File'!A:A,A2,'Player Stats Master File'!N:N) -> 0.89880573 | H3: =sum(C3:G3) -> 44.831802
H4: Total Points for Winning/Accolades
H5: =sum(C7:C26) -> 50.25
A6: Points for Accolades | C6: Player Points | H6: Career Player Score
A7: 1st_NBA | B7: 3 | C7: =(sumif('Player Winning & Accolades Mast'!A:A,A2,'Player Winning & Accolades Mast'!B:B))*B7 -> 3 | H7: =H5+H3 -> 95.081802
A8: 2nd_NBA | B8: 2 | C8: =(sumif('Player Winning & Accolades Mast'!A:A,A2,'Player Winning & Accolades Mast'!C:C))*B8 -> 8
A9: 3rd_NBA | B9: 1 | C9: =(sumif('Player Winning & Accolades Mast'!A:A,A2,'Player Winning & Accolades Mast'!D:D))*B9 -> 2
A10: 1st_Def | B10: 2 | C10: =(sumif('Player Winning & Accolades Mast'!A:A,A2,'Player Winning & Accolades Mast'!E:E))*B10 -> 0
A11: 2nd_Def | B11: 1 | C11: =(sumif('Player Winning & Accolades Mast'!A:A,A2,'Player Winning & Accolades Mast'!F:F))*B11 -> 0
A12: NBA Championship | B12: 4 | C12: =sumif('Player Winning & Accolades Mast'!A:A,A2,'Player Winning & Accolades Mast'!H:H)*B12 -> 0
A13: NBA_Finals_MVP | B13: 2 | C13: =sumif('Player Winning & Accolades Mast'!A:A,A2,'Player Winning & Accolades Mast'!I:I)*B13 -> 0
A14: Regular_Season_MVP | B14: 5 | C14: =sumif('Player Winning & Accolades Mast'!A:A,A2,'Player Winning & Accolades Mast'!J:J)*B14 -> 0
A15: DPOY | B15: 4 | C15: =sumif('Player Winning & Accolades Mast'!A:A,A2,'Player Winning & Accolades Mast'!K:K)*B15 -> 0
A16: ROY | B16: 3 | C16: =sumif('Player Winning & Accolades Mast'!A:A,A2,'Player Winning & Accolades Mast'!L:L)*B16 -> 0
A17: 6MOY | B17: 2 | C17: =sumif('Player Winning & Accolades Mast'!A:A,A2,'Player Winning & Accolades Mast'!M:M)*B17 -> 0
A18: All-Star_Games | B18: 0.25 | C18: =sumif('Player Winning & Accolades Mast'!A:A,A2,'Player Winning & Accolades Mast'!N:N)*B18 -> 1.75
A19: Scoring_Title | B19: 1.5 | C19: =sumif('Player Winning & Accolades Mast'!A:A,A2,'Player Winning & Accolades Mast'!O:O)*B19 -> 1.5
A20: Assists_Leader | B20: 1 | C20: =sumif('Player Winning & Accolades Mast'!A:A,A2,'Player Winning & Accolades Mast'!P:P)*B20 -> 0
A21: Rebounding_Leader | B21: 1 | C21: =sumif('Player Winning & Accolades Mast'!A:A,A2,'Player Winning & Accolades Mast'!Q:Q)*B21 -> 0
A22: Steals_Leader | B22: 1 | C22: =sumif('Player Winning & Accolades Mast'!A:A,A2,'Player Winning & Accolades Mast'!R:R)*B22 -> 0
A23: Blocks_Leader | B23: 1 | C23: =sumif('Player Winning & Accolades Mast'!A:A,A2,'Player Winning & Accolades Mast'!S:S)*B23 -> 0
A24: Regular Season Winning PCT | B24: Bucketized Performance (0,1,2,3) | C24: =IF(D24="Bucket 1",3,IF(D24 = "Bucket 2",1.5,0)) -> 0 | D24: =IF(SUMIF('Player Stats Master File'!AK:AK,A2,'Player Stats Master File'!AM:AM) > 0.7,"Bucket 1",IF(SUMIF('Player Stats Master File'!AK:AK,A2,'Player Stats Master File'!AM:AM)> 0.6,"Bucket 2","Bucket 3")) -> Bucket 3
A25: Playoff Wining PCT | B25: Bucketized Performance (0,1,2,3) | C25: =IF(D25="Bucket 1",3,IF(D25 = "Bucket 2",1.5,0)) -> 0 | D25: =IF(SUMIF('Player Stats Master File'!AK:AK,A2,'Player Stats Master File'!AN:AN) > 0.6,"Bucket 1",IF(SUMIF('Player Stats Master File'!AK:AK,A2,'Player Stats Master File'!AN:AN)> 0.55,"Bucket 2","Bucket 3")) -> Bucket 3
A26: Legacy_Impact | B26: 0-50 | C26: =sumif('Player Winning & Accolades Mast'!A:A,A2,'Player Winning & Accolades Mast'!V:V) -> 34

Sheet All-Time List
D1: Top 32 All-Time LIST
A2: Player | B2: Total Points From All Criteria | D2: Player | E2: Total Points From All Criteria | G2: All Time Rank
A3: Allen Iverson | B3: 128.48 | D3: Michael Jordan | E3: 250.28 | G3: 1
A4: Bill Russell | B4: 200.35 | D4: Kareem Abdul-Jabbar | E4: 233.04 | G4: 2
A5: Bob Cousy | B5: 131.93 | D5: LeBron James | E5: 226.39 | G5: =G4+1 -> 3
A6: Chris Paul | B6: 117.76 | D6: Bill Russell | E6: 202.35 | G6: =G5+1 -> 4
A7: David Robinson | B7: 139.32 | D7: Kobe Bryant | E7: 200.04 | G7: =G6+1 -> 5
A8: Dirk Nowitzki | B8: 106.59 | D8: Wilt Chamberlain | E8: 195.28 | G8: =G7+1 -> 6
A9: Dominique Wilkins | B9: 94.08 | D9: Tim Duncan | E9: 192.82 | G9: =G8+1 -> 7
A10: Dwyane Wade | B10: 113.85 | D10: Magic Johnson | E10: 184.13 | G10: =G9+1 -> 8
A11: Gary Payton | B11: 118.92 | D11: Larry Bird | E11: 179.22 | G11: =G10+1 -> 9
A12: Hakeem Olajuwon | B12: 161.64 | D12: Shaquille O'Neal | E12: 174.43 | G12: =G11+1 -> 10
A13: Isiah Thomas | B13: 105.41 | D13: Hakeem Olajuwon | E13: 158.64 | G13: =G12+1 -> 11
A14: Jason Kidd | B14: 113.5 | D14: Stephen Curry | E14: 157.72 | G14: =G13+1 -> 12
A15: Jerry West | B15: 148.84 | D15: Julius Erving | E15: 152.18 | G15: =G14+1 -> 13
A16: John Havlicek | B16: 136.16 | D16: Jerry West | E16: 148.84 | G16: =G15+1 -> 14
... A30: Tim Duncan | B30: 182.82 | D30: Jason Kidd | E30: 117.05 | G30: =G29+1 -> 28
A31: Wilt Chamberlain | D31: Dirk Nowitzki | E31: 106.59 | G31: =G30+1 -> 29
A32: Giannis Antetokounmpo | B32: 146.31 | D32: Isiah Thomas | E32: 105.41 | G32: =G31+1 -> 30
A33: Nikola JokiÄ‡ | B33: 127.2 | D33: John Stockton | E33: 104.79 | G33: =G32+1 -> 31
A34: Moses Malone | B34: 133.35 | D34: Dominique Wilkins | E34: 95.08 | G34: =G33+1 -> 32
A35: Wilt Chamberlain | B35: 194.78
